<?xml version="1.0"?>
<robot xmlns:xacro="http://www.ros.org/wiki/xacro" >

    <xacro:include filename="inertial_macros.xacro"/>

    <material name="white">
        <color rgba="1 1 1 1" />
    </material>

    <material name="orange">
        <color rgba="1 0.3 0.1 1"/>
    </material>

    <material name="blue">
        <color rgba="0.2 0.2 1 1"/>
    </material>

    <material name="black">
        <color rgba="0 0 0 1"/>
    </material>


    <link name="base_link">

    </link>



    <joint name="chassis_joint" type="fixed">
        <parent link="base_link"/>
        <child link="chassis"/>
        <origin xyz="-0.1 0 0"/>
    </joint>

    <link name="chassis">
        <visual>
            <origin xyz="0.25 0 0.12"/>
            <geometry>
                <box size="0.5 0.3 0.1"/>
            </geometry>
            <material name="white"/>
        </visual>
        <collision>
            <origin xyz="0.15 0 0.075"/>
            <geometry>
                <box size="0.3 0.3 0.15"/>
            </geometry>
        </collision>
        <xacro:inertial_box mass="0.5" x="0.3" y="0.3" z="0.15">
            <origin xyz="0.15 0 0.075" rpy="0 0 0"/>
        </xacro:inertial_box>
    </link>

    <gazebo reference="chassis">
        <material>Gazebo/Red</material>
    </gazebo>


    <joint name="left_wheel_joint" type="continuous">
        <parent link="base_link"/>
        <child link="left_wheel"/>
        <origin xyz="0 0.175 0" rpy="-${pi/2} 0 0" />
        <axis xyz="0 0 1"/>
    </joint>

    <link name="left_wheel">
        <visual>
            <geometry>
                <cylinder radius="0.05" length="0.04"/>
            </geometry>
            <material name="blue"/>
        </visual>
        <collision>
            <geometry>
                <cylinder radius="0.05" length="0.04"/>
            </geometry>
        </collision>
        <xacro:inertial_cylinder mass="0.1" length="0.04" radius="0.05">
            <origin xyz="0 0 0" rpy="0 0 0"/>
        </xacro:inertial_cylinder>
    </link>

    <gazebo reference="left_wheel">
        <material>Gazebo/Blue</material>
    </gazebo>


    <joint name="left_wheel_joint_2" type="continuous">
        <parent link="base_link"/>
        <child link="left_wheel_2"/>
        <origin xyz="0.3 0.175 0" rpy="-${pi/2} 0 0" />
        <axis xyz="0 0 1"/>
    </joint>

    <link name="left_wheel_2">
        <visual>
            <geometry>
                <cylinder radius="0.05" length="0.04"/>
            </geometry>
            <material name="blue"/>
        </visual>
        <collision>
            <geometry>
                <cylinder radius="0.05" length="0.04"/>
            </geometry>
        </collision>
        <xacro:inertial_cylinder mass="0.1" length="0.04" radius="0.05">
            <origin xyz="0 0 0" rpy="0 0 0"/>
        </xacro:inertial_cylinder>
    </link>

    <gazebo reference="left_wheel_2">
        <material>Gazebo/Blue</material>
    </gazebo>

    <joint name="right_wheel_joint" type="continuous">
        <parent link="base_link"/>
        <child link="right_wheel"/>
        <origin xyz="0 -0.175 0" rpy="${pi/2} 0 0" />
        <axis xyz="0 0 -1"/>
    </joint>

    <link name="right_wheel">
        <visual>
            <geometry>
                <cylinder radius="0.05" length="0.04"/>
            </geometry>
            <material name="blue"/>
        </visual>
        <collision>
            <geometry>
                <cylinder radius="0.05" length="0.04"/>
            </geometry>
        </collision>
        <xacro:inertial_cylinder mass="0.1" length="0.04" radius="0.05">
            <origin xyz="0 0 0" rpy="0 0 0"/>
        </xacro:inertial_cylinder>
    </link>

    <gazebo reference="right_wheel">
        <material>Gazebo/Blue</material>
    </gazebo>



    <joint name="right_wheel_joint_2" type="continuous">
        <parent link="base_link"/>
        <child link="right_wheel_2"/>
        <origin xyz="0.3 -0.175 0" rpy="${pi/2} 0 0" />
        <axis xyz="0 0 -1"/>
    </joint>

    <link name="right_wheel_2">
        <visual>
            <geometry>
                <cylinder radius="0.05" length="0.04"/>
            </geometry>
            <material name="blue"/>
        </visual>
        <collision>
            <geometry>
                <cylinder radius="0.05" length="0.04"/>
            </geometry>
        </collision>
        <xacro:inertial_cylinder mass="0.1" length="0.04" radius="0.05">
            <origin xyz="0 0 0" rpy="0 0 0"/>
        </xacro:inertial_cylinder>
    </link>

    <gazebo reference="right_wheel_2">
        <material>Gazebo/Blue</material>
    </gazebo>

    
    

     
    
    <!-- 1) ZED2 Kameranın Ana Gövde Link'i ve Görünümü -->

<link name="zed2_camera_link">
  <visual>
    <geometry><box size="0.010 0.03 0.03"/></geometry>
    <material name="black"/>
  </visual>
</link>

<joint name="zed2_camera_joint" type="fixed">
  <parent link="base_link"/>
  <child  link="zed2_camera_link"/>
  <origin xyz="0.39 0 0.195" rpy="0 0 0"/>
</joint>


<link name="zed2_left_optical_frame">
  <pose>-0.06 0 0 0 0 0</pose>
</link>

<joint name="zed2_left_optical_joint" type="fixed">
  <parent link="zed2_camera_link"/>
  <child  link="zed2_left_optical_frame"/>
  <origin xyz="0 0 0" rpy="0 0 0"/>
</joint>

<link name="zed2_right_optical_frame">
  <pose>0.06 0 0  0 -1.5708 -1.5708</pose>
</link>

<joint name="zed2_right_optical_joint" type="fixed">
  <parent link="zed2_camera_link"/>
  <child  link="zed2_right_optical_frame"/>
  <origin xyz="0 0 0" rpy="0 0 0"/>
</joint>


<gazebo reference="zed2_left_optical_frame">
  <sensor name="zed2_left_rgb" type="camera">
    <update_rate>30</update_rate>
    <camera>
      <horizontal_fov>1.047</horizontal_fov>
      <image>
        <width>1280</width><height>720</height><format>R8G8B8</format>
      </image>
      <clip><near>0.1</near><far>30.0</far></clip>
    </camera>

    <plugin name="zed2_left_rgb_plugin" filename="libgazebo_ros_camera.so">
      <ros><namespace>/zed2/left</namespace></ros>
      <cameraName>zed2_left</cameraName>
      <imageTopicName>image_raw</imageTopicName>
      <cameraInfoTopicName>camera_info</cameraInfoTopicName>
      <frameName>zed2_left_optical_frame</frameName>
      <alwaysOn>true</alwaysOn>
    </plugin>
  </sensor>
</gazebo>

<gazebo reference="zed2_camera_link">
        <material>Gazebo/Black</material>
    </gazebo>

<gazebo reference="zed2_right_optical_frame">
  <sensor name="zed2_right_depth" type="depth">
    <always_on>true</always_on>
    <update_rate>30</update_rate>
    <camera name="zed2_right_depth_cam">
      <horizontal_fov>1.047</horizontal_fov>
      <image>
        <width>1280</width><height>720</height><format>R8G8B8</format>
      </image>
      <clip><near>0.1</near><far>30.0</far></clip>
    </camera>

    <plugin name="zed2_right_depth_plugin" filename="libgazebo_ros_camera.so">
      <ros><namespace>/zed2/right</namespace></ros>
      <cameraName>zed2_right_depth</cameraName>
      <frameName>zed2_right_opticalframe</frameName>

      <depthImageTopicName>depth/image_raw</depthImageTopicName>
      <depthImageCameraInfoTopicName>depth/camera_info</depthImageCameraInfoTopicName>
      <pointCloudTopicName>depth/points</pointCloudTopicName>

      <pointCloudCutoff>0.1</pointCloudCutoff>
      <pointCloudCutoffMax>30.0</pointCloudCutoffMax>
      <alwaysOn>true</alwaysOn>
    </plugin>
  </sensor>
</gazebo>

  


</robot>